2018-10-28 20:05:35,828 ERROR: Exception on /user/user 1 [GET] [in /Users/nilesh/contact-book/venv/lib/python3.7/site-packages/flask/app.py:1761]
Traceback (most recent call last):
  File "/Users/nilesh/contact-book/venv/lib/python3.7/site-packages/flask/app.py", line 2292, in wsgi_app
    response = self.full_dispatch_request()
  File "/Users/nilesh/contact-book/venv/lib/python3.7/site-packages/flask/app.py", line 1815, in full_dispatch_request
    rv = self.handle_user_exception(e)
  File "/Users/nilesh/contact-book/venv/lib/python3.7/site-packages/flask/app.py", line 1718, in handle_user_exception
    reraise(exc_type, exc_value, tb)
  File "/Users/nilesh/contact-book/venv/lib/python3.7/site-packages/flask/_compat.py", line 35, in reraise
    raise value
  File "/Users/nilesh/contact-book/venv/lib/python3.7/site-packages/flask/app.py", line 1813, in full_dispatch_request
    rv = self.dispatch_request()
  File "/Users/nilesh/contact-book/venv/lib/python3.7/site-packages/flask/app.py", line 1799, in dispatch_request
    return self.view_functions[rule.endpoint](**req.view_args)
  File "/Users/nilesh/contact-book/venv/lib/python3.7/site-packages/flask_login/utils.py", line 228, in decorated_view
    return func(*args, **kwargs)
  File "/Users/nilesh/contact-book/app/main/routes.py", line 60, in user
    posts = user.posts.order_by(Post.timestamp.desc()).paginate(
AttributeError: 'User' object has no attribute 'posts'
2018-10-28 20:06:44,630 ERROR: Exception on /index [POST] [in /Users/nilesh/contact-book/venv/lib/python3.7/site-packages/flask/app.py:1761]
Traceback (most recent call last):
  File "/Users/nilesh/contact-book/venv/lib/python3.7/site-packages/sqlalchemy/engine/base.py", line 1182, in _execute_context
    context)
  File "/Users/nilesh/contact-book/venv/lib/python3.7/site-packages/sqlalchemy/engine/default.py", line 470, in do_execute
    cursor.execute(statement, parameters)
sqlite3.InterfaceError: Error binding parameter 4 - probably unsupported type.

The above exception was the direct cause of the following exception:

Traceback (most recent call last):
  File "/Users/nilesh/contact-book/venv/lib/python3.7/site-packages/flask/app.py", line 2292, in wsgi_app
    response = self.full_dispatch_request()
  File "/Users/nilesh/contact-book/venv/lib/python3.7/site-packages/flask/app.py", line 1815, in full_dispatch_request
    rv = self.handle_user_exception(e)
  File "/Users/nilesh/contact-book/venv/lib/python3.7/site-packages/flask/app.py", line 1718, in handle_user_exception
    reraise(exc_type, exc_value, tb)
  File "/Users/nilesh/contact-book/venv/lib/python3.7/site-packages/flask/_compat.py", line 35, in reraise
    raise value
  File "/Users/nilesh/contact-book/venv/lib/python3.7/site-packages/flask/app.py", line 1813, in full_dispatch_request
    rv = self.dispatch_request()
  File "/Users/nilesh/contact-book/venv/lib/python3.7/site-packages/flask/app.py", line 1799, in dispatch_request
    return self.view_functions[rule.endpoint](**req.view_args)
  File "/Users/nilesh/contact-book/venv/lib/python3.7/site-packages/flask_login/utils.py", line 228, in decorated_view
    return func(*args, **kwargs)
  File "/Users/nilesh/contact-book/app/main/routes.py", line 32, in index
    db.session.commit()
  File "/Users/nilesh/contact-book/venv/lib/python3.7/site-packages/sqlalchemy/orm/scoping.py", line 157, in do
    return getattr(self.registry(), name)(*args, **kwargs)
  File "/Users/nilesh/contact-book/venv/lib/python3.7/site-packages/sqlalchemy/orm/session.py", line 906, in commit
    self.transaction.commit()
  File "/Users/nilesh/contact-book/venv/lib/python3.7/site-packages/sqlalchemy/orm/session.py", line 461, in commit
    self._prepare_impl()
  File "/Users/nilesh/contact-book/venv/lib/python3.7/site-packages/sqlalchemy/orm/session.py", line 441, in _prepare_impl
    self.session.flush()
  File "/Users/nilesh/contact-book/venv/lib/python3.7/site-packages/sqlalchemy/orm/session.py", line 2177, in flush
    self._flush(objects)
  File "/Users/nilesh/contact-book/venv/lib/python3.7/site-packages/sqlalchemy/orm/session.py", line 2297, in _flush
    transaction.rollback(_capture_exception=True)
  File "/Users/nilesh/contact-book/venv/lib/python3.7/site-packages/sqlalchemy/util/langhelpers.py", line 66, in __exit__
    compat.reraise(exc_type, exc_value, exc_tb)
  File "/Users/nilesh/contact-book/venv/lib/python3.7/site-packages/sqlalchemy/util/compat.py", line 187, in reraise
    raise value
  File "/Users/nilesh/contact-book/venv/lib/python3.7/site-packages/sqlalchemy/orm/session.py", line 2261, in _flush
    flush_context.execute()
  File "/Users/nilesh/contact-book/venv/lib/python3.7/site-packages/sqlalchemy/orm/unitofwork.py", line 389, in execute
    rec.execute(self)
  File "/Users/nilesh/contact-book/venv/lib/python3.7/site-packages/sqlalchemy/orm/unitofwork.py", line 548, in execute
    uow
  File "/Users/nilesh/contact-book/venv/lib/python3.7/site-packages/sqlalchemy/orm/persistence.py", line 181, in save_obj
    mapper, table, insert)
  File "/Users/nilesh/contact-book/venv/lib/python3.7/site-packages/sqlalchemy/orm/persistence.py", line 835, in _emit_insert_statements
    execute(statement, params)
  File "/Users/nilesh/contact-book/venv/lib/python3.7/site-packages/sqlalchemy/engine/base.py", line 945, in execute
    return meth(self, multiparams, params)
  File "/Users/nilesh/contact-book/venv/lib/python3.7/site-packages/sqlalchemy/sql/elements.py", line 263, in _execute_on_connection
    return connection._execute_clauseelement(self, multiparams, params)
  File "/Users/nilesh/contact-book/venv/lib/python3.7/site-packages/sqlalchemy/engine/base.py", line 1053, in _execute_clauseelement
    compiled_sql, distilled_params
  File "/Users/nilesh/contact-book/venv/lib/python3.7/site-packages/sqlalchemy/engine/base.py", line 1189, in _execute_context
    context)
  File "/Users/nilesh/contact-book/venv/lib/python3.7/site-packages/sqlalchemy/engine/base.py", line 1402, in _handle_dbapi_exception
    exc_info
  File "/Users/nilesh/contact-book/venv/lib/python3.7/site-packages/sqlalchemy/util/compat.py", line 203, in raise_from_cause
    reraise(type(exception), exception, tb=exc_tb, cause=cause)
  File "/Users/nilesh/contact-book/venv/lib/python3.7/site-packages/sqlalchemy/util/compat.py", line 186, in reraise
    raise value.with_traceback(tb)
  File "/Users/nilesh/contact-book/venv/lib/python3.7/site-packages/sqlalchemy/engine/base.py", line 1182, in _execute_context
    context)
  File "/Users/nilesh/contact-book/venv/lib/python3.7/site-packages/sqlalchemy/engine/default.py", line 470, in do_execute
    cursor.execute(statement, parameters)
sqlalchemy.exc.InterfaceError: <unprintable InterfaceError object>
2018-10-28 20:20:48,982 INFO: Service startup [in /Users/nilesh/contact-book/app/__init__.py:74]
2018-10-28 20:36:55,126 INFO: Service startup [in /Users/nilesh/contact-book/app/__init__.py:74]
